<?xml version="1.0" ?>
<!-- =================================================================================== -->
<!-- |    This document was autogenerated by xacro from panda_arm.urdf.xacro           | -->
<!-- |    EDITING THIS FILE BY HAND IS NOT RECOMMENDED                                 | -->
<!-- =================================================================================== -->
<robot name="panda_left">
  <link name="panda_left_link0">
    <visual>
      <geometry>
        <mesh filename="../franka_description/meshes/visual/link0.glb"/>
      </geometry>
    </visual>
    <collision>
      <geometry>
        <mesh filename="../franka_description/meshes/collision/link0.stl"/>
      </geometry>
    </collision>
    <inertial>
      <origin rpy="0 0 0" xyz="-0.041018 -0.00014 0.049974"/>
      <mass value="0.629769"/>
      <inertia ixx="0.00315" ixy="8.2904e-07" ixz="0.00015" iyy="0.00388" iyz="8.2299e-06" izz="0.004285"/>
    </inertial>
  </link>
  <link name="panda_left_link1">
    <visual>
      <geometry>
        <mesh filename="../franka_description/meshes/visual/link1.glb"/>
      </geometry>
    </visual>
    <collision>
      <geometry>
        <mesh filename="../franka_description/meshes/collision/link1.stl"/>
      </geometry>
    </collision>
    <inertial>
      <origin rpy="0 0 0" xyz="0.003875 0.002081 -0.04762"/>
      <mass value="4.970684"/>
      <inertia ixx="0.70337" ixy="-0.000139" ixz="0.006772" iyy="0.70661" iyz="0.019169" izz="0.009117"/>
    </inertial>
  </link>
  <joint name="panda_left_joint1" type="revolute">
    <safety_controller k_position="100.0" k_velocity="40.0" soft_lower_limit="-2.8973" soft_upper_limit="2.8973"/>
    <origin rpy="0 0 0" xyz="0 0 0.333"/>
    <parent link="panda_left_link0"/>
    <child link="panda_left_link1"/>
    <axis xyz="0 0 1"/>
    <limit effort="87" lower="-2.8973" upper="2.8973" velocity="2.1750"/>
    <dynamics D="1" K="7000" damping="0.003" friction="0.0" mu_coulomb="0" mu_viscous="16"/>
  </joint>
  <link name="panda_left_link2">
    <visual>
      <geometry>
        <mesh filename="../franka_description/meshes/visual/link2.glb"/>
      </geometry>
    </visual>
    <collision>
      <geometry>
        <mesh filename="../franka_description/meshes/collision/link2.stl"/>
      </geometry>
    </collision>
    <inertial>
      <origin rpy="0 0 0" xyz="-0.003141 -0.02872  0.003495"/>
      <mass value="0.646926"/>
      <inertia ixx="0.007962" ixy="-0.003925" ixz="0.010254" iyy="0.02811" iyz="0.000704" izz="0.025995"/>
    </inertial>
  </link>
  <joint name="panda_left_joint2" type="revolute">
    <safety_controller k_position="100.0" k_velocity="40.0" soft_lower_limit="-1.7628" soft_upper_limit="1.7628"/>
    <origin rpy="-1.5707963267948966 0 0" xyz="0 0 0"/>
    <parent link="panda_left_link1"/>
    <child link="panda_left_link2"/>
    <axis xyz="0 0 1"/>
    <limit effort="87" lower="-1.7628" upper="1.7628" velocity="2.1750"/>
    <dynamics D="1" K="7000" damping="0.003" friction="0.0" mu_coulomb="0" mu_viscous="16"/>
  </joint>
  <link name="panda_left_link3">
    <visual>
      <geometry>
        <mesh filename="../franka_description/meshes/visual/link3.glb"/>
      </geometry>
    </visual>
    <collision>
      <geometry>
        <mesh filename="../franka_description/meshes/collision/link3.stl"/>
      </geometry>
    </collision>
    <inertial>
      <origin rpy="0 0 0" xyz="2.7518e-02 3.9252e-02 -6.6502e-02"/>
      <mass value="3.228604"/>
      <inertia ixx="0.037242" ixy="-0.004761" ixz="-0.011396" iyy="0.036155" iyz="-0.012805" izz="0.01083"/>
    </inertial>
  </link>
  <joint name="panda_left_joint3" type="revolute">
    <safety_controller k_position="100.0" k_velocity="40.0" soft_lower_limit="-2.8973" soft_upper_limit="2.8973"/>
    <origin rpy="1.5707963267948966 0 0" xyz="0 -0.316 0"/>
    <parent link="panda_left_link2"/>
    <child link="panda_left_link3"/>
    <axis xyz="0 0 1"/>
    <limit effort="87" lower="-2.8973" upper="2.8973" velocity="2.1750"/>
    <dynamics D="1" K="7000" damping="0.003" friction="0.0" mu_coulomb="0" mu_viscous="16"/>
  </joint>
  <link name="panda_left_link4">
    <visual>
      <geometry>
        <mesh filename="../franka_description/meshes/visual/link4.glb"/>
      </geometry>
    </visual>
    <collision>
      <geometry>
        <mesh filename="../franka_description/meshes/collision/link4.stl"/>
      </geometry>
    </collision>
    <inertial>
      <origin rpy="0 0 0" xyz="-5.317e-02 1.04419e-01 2.7454e-02"/>
      <mass value="3.587895"/>
      <inertia ixx="0.025853" ixy="0.007796" ixz="-0.001332" iyy="0.019552" iyz="0.008641" izz="0.028323"/>
    </inertial>
  </link>
  <joint name="panda_left_joint4" type="revolute">
    <safety_controller k_position="100.0" k_velocity="40.0" soft_lower_limit="-3.0718" soft_upper_limit="-0.0698"/>
    <origin rpy="1.5707963267948966 0 0" xyz="0.0825 0 0"/>
    <parent link="panda_left_link3"/>
    <child link="panda_left_link4"/>
    <axis xyz="0 0 1"/>
    <limit effort="87" lower="-3.0718" upper="-0.0698" velocity="2.1750"/>
    <dynamics D="1" K="7000" damping="0.003" friction="0.0" mu_coulomb="0" mu_viscous="16"/>
  </joint>
  <link name="panda_left_link5">
    <visual>
      <geometry>
        <mesh filename="../franka_description/meshes/visual/link5.glb"/>
      </geometry>
    </visual>
    <collision>
      <geometry>
        <mesh filename="../franka_description/meshes/collision/link5.stl"/>
      </geometry>
    </collision>
    <inertial>
      <origin rpy="0 0 0" xyz="-1.1953e-02 4.1065e-02 -3.8437e-02"/>
      <mass value="1.225946"/>
      <inertia ixx="0.035549" ixy="-0.002117" ixz="-0.004037" iyy="0.029474" iyz="0.000229" izz="0.008627"/>
    </inertial>
  </link>
  <joint name="panda_left_joint5" type="revolute">
    <safety_controller k_position="100.0" k_velocity="40.0" soft_lower_limit="-2.8973" soft_upper_limit="2.8973"/>
    <origin rpy="-1.5707963267948966 0 0" xyz="-0.0825 0.384 0"/>
    <parent link="panda_left_link4"/>
    <child link="panda_left_link5"/>
    <axis xyz="0 0 1"/>
    <limit effort="12" lower="-2.8973" upper="2.8973" velocity="2.6100"/>
    <dynamics D="1" K="7000" damping="0.003" friction="0.0" mu_coulomb="0" mu_viscous="16"/>
  </joint>
  <link name="panda_left_link6">
    <visual>
      <geometry>
        <mesh filename="../franka_description/meshes/visual/link6.glb"/>
      </geometry>
    </visual>
    <collision>
      <geometry>
        <mesh filename="../franka_description/meshes/collision/link6.stl"/>
      </geometry>
    </collision>
    <inertial>
      <origin rpy="0 0 0" xyz="6.0149e-02 -1.4117e-02 -1.0517e-02"/>
      <mass value="1.666555"/>
      <inertia ixx="0.001964" ixy="0.000109" ixz="-0.001158" iyy="0.004354" iyz="0.000341" izz="0.005433"/>
    </inertial>
  </link>
  <joint name="panda_left_joint6" type="revolute">
    <safety_controller k_position="100.0" k_velocity="40.0" soft_lower_limit="-0.0175" soft_upper_limit="3.7525"/>
    <origin rpy="1.5707963267948966 0 0" xyz="0 0 0"/>
    <parent link="panda_left_link5"/>
    <child link="panda_left_link6"/>
    <axis xyz="0 0 1"/>
    <limit effort="12" lower="-0.0175" upper="3.7525" velocity="2.6100"/>
    <dynamics D="1" K="7000" damping="0.003" friction="0.0" mu_coulomb="0" mu_viscous="16"/>
  </joint>
  <link name="panda_left_link7">
    <visual>
      <geometry>
        <mesh filename="../franka_description/meshes/visual/link7.glb"/>
      </geometry>
    </visual>
    <collision>
      <geometry>
        <mesh filename="../franka_description/meshes/collision/link7.stl"/>
      </geometry>
    </collision>
    <inertial>
      <origin rpy="0 0 0" xyz="1.0517e-02 -4.252e-03 6.1597e-02"/>
      <mass value="0.735522"/>
      <inertia ixx="0.012516" ixy="-0.000428" ixz="-0.001196" iyy="0.010027" iyz="-0.000741" izz="0.004815"/>
    </inertial>
  </link>
  <joint name="panda_left_joint7" type="revolute">
    <safety_controller k_position="100.0" k_velocity="40.0" soft_lower_limit="-2.8973" soft_upper_limit="2.8973"/>
    <origin rpy="1.5707963267948966 0 0" xyz="0.088 0 0"/>
    <parent link="panda_left_link6"/>
    <child link="panda_left_link7"/>
    <axis xyz="0 0 1"/>
    <limit effort="12" lower="-2.8973" upper="2.8973" velocity="2.6100"/>
    <dynamics D="1" K="7000" damping="0.003" friction="0.0" mu_coulomb="0" mu_viscous="16"/>
  </joint>
  <link name="panda_left_link8"/>
  <joint name="panda_left_joint8" type="fixed">
    <origin rpy="0 0 0" xyz="0 0 0.000"/>
    <parent link="panda_left_link7"/>
    <child link="panda_left_link8"/>
  </joint>
  <joint name="tesollo_left_mount_joint" type="fixed">
    <origin xyz="0 0 0.1034" rpy="0 0 0"/>
    <parent link="panda_left_link8"/>
    <child link="ll_dg_mount"/>
  </joint>

  <!-- tesollo hand -->
  <link name="ll_dg_mount">
    <inertial>
      <origin xyz="6.4721E-09 2.1674E-05 0.0049997" rpy="0.0 0.0 0.0" />
      <inertia ixx="1.0999E-05" ixy="-2.1734E-12" ixz="-1.2441E-12" iyy="1.1018E-05" iyz="-4.0435E-09" izz="2.0531E-05" />
      <mass value="0.05" />
    </inertial>
    <visual>
      <geometry>
        <mesh filename="../meshes/dg5f_left/visual/ll_dg_mount.dae"/>
      </geometry>
    </visual>
    <collision>
      <geometry>
        <mesh filename="../meshes/dg5f_left/collision/ll_dg_mount_c.STL"/>
      </geometry>
    </collision>
  </link>

  <link name="ll_dg_base">
    <inertial>
      <origin xyz="-0.00058969 -0.00051381 0.037363" rpy="0.0 0.0 0.0" />
      <inertia ixx="0.00048608" ixy="-1.041E-05" ixz="1.7229E-05" iyy="0.00049085" iyz="5.191E-06" izz="0.00043369" />
      <mass value="0.45" />
    </inertial>
    <visual>
      <origin xyz="0 0 0" rpy="0 0 0" />
      <geometry>
        <mesh filename="../meshes/dg5f_left/visual/ll_dg_base.dae" />
      </geometry>
    </visual>
    <collision>
      <origin xyz="0 0 0" rpy="0 0 0" />
      <geometry>
        <mesh filename="../meshes/dg5f_left/collision/ll_dg_base_c.STL" />
      </geometry>
    </collision>
  </link>
  <joint name="lj_dg_base" type="fixed">
    <parent link="ll_dg_mount"/>
    <child link="ll_dg_base"/>
    <origin rpy="0 0 0" xyz="0 0 0.004"/>
  </joint>

  <link name="ll_dg_palm">
    <inertial>
      <origin xyz="-0.0089544 -0.00095674 0.041327" rpy="0.0 0.0 0.0" />
      <inertia ixx="0.00052648" ixy="-2.618E-06" ixz="-2.2256E-05" iyy="0.00041644" iyz="4.8923E-05" izz="0.00045776" />
      <mass value="0.35" />
    </inertial>
    <visual>
      <origin xyz="0 0 0" rpy="0 0 0" />
      <geometry>
        <mesh filename="../meshes/dg5f_left/visual/ll_dg_palm.dae" />
      </geometry>
    </visual>
    <collision>
      <origin xyz="0 0 0" rpy="0 0 0" />
      <geometry>
        <mesh filename="../meshes/dg5f_left/collision/ll_dg_palm_c.STL" />
      </geometry>
    </collision>
  </link>
  <joint name="lj_dg_palm" type="fixed">
    <parent link="ll_dg_base"/>
    <child link="ll_dg_palm"/>
    <origin rpy="0 0 0" xyz="0 0 0.0698"/>
  </joint>

  <link name="ll_dg_1_1">
    <inertial>
      <origin xyz="0.021473 3.1163E-06 0.0028146" rpy="0.0 0.0 0.0" />
      <inertia ixx="4.2707E-06" ixy="2.4123E-09" ixz="2.9055E-06" iyy="1.3718E-05" iyz="-1.3824E-09" izz="1.2161E-05" />
      <mass value="0.045" />
    </inertial>
    <visual>
      <origin xyz="0 0 0" rpy="0 0 0" />
      <geometry>
        <mesh filename="../meshes/dg5f_left/visual/ll_dg_1_1.dae" />
      </geometry>
    </visual>
    <collision>
      <origin xyz="0 0 0" rpy="0 0 0" />
      <geometry>
        <mesh filename="../meshes/dg5f_left/collision/ll_dg_1_1_c.STL" />
      </geometry>
    </collision>
  </link>
  <joint name="lj_dg_1_1" type="revolute">
    <origin xyz="-0.0162 -0.019 0.0128" rpy="0.0 0.0 0.0" />
    <parent link="ll_dg_palm" />
    <child link="ll_dg_1_1" />
    <axis xyz="1 0 0" />
    <limit lower="-0.8901179185171081" upper="0.3839724354387525" effort="7.5" velocity="3.141592653589793"/>
  </joint>

  <link name="ll_dg_1_2">
    <inertial>
      <origin xyz="-0.00055633 -0.0155 0.00055633" rpy="0.0 0.0 0.0" />
      <inertia ixx="1.9935E-06" ixy="-1.5774E-07" ixz="-3.114E-09" iyy="1.459E-06" iyz="-1.5774E-07" izz="1.9935E-06" />
      <mass value="0.025" />
    </inertial>
    <visual>
      <origin xyz="0 0 0" rpy="0 0 0" />
      <geometry>
        <mesh filename="../meshes/dg5f_left/visual/ll_dg_1_2.dae" />
      </geometry>
    </visual>
    <collision>
      <origin xyz="0 0 0" rpy="0 0 0" />
      <geometry>
        <mesh filename="../meshes/dg5f_left/collision/ll_dg_1_2_c.STL" />
      </geometry>
    </collision>
  </link>
  <joint name="lj_dg_1_2" type="revolute">
    <origin xyz="0.04195 0.0 0.0" rpy="0.0 0.0 0.0" />
    <parent link="ll_dg_1_1" />
    <child link="ll_dg_1_2" />
    <axis xyz="0 0 1" />
    <limit lower="-0.0" upper="3.141592653589793" effort="7.5" velocity="3.141592653589793"/>
  </joint>

  <link name="ll_dg_1_3">
    <inertial>
      <origin xyz="-2.3008E-05 -0.014842 4.7446E-06" rpy="0.0 0.0 0.0" />
      <inertia ixx="5.9794E-06" ixy="-3.6014E-07" ixz="1.3678E-09" iyy="2.458E-06" iyz="2.3552E-09" izz="6.4181E-06" />
      <mass value="0.045" />
    </inertial>
    <visual>
      <origin xyz="0 0 0" rpy="0 0 0" />
      <geometry>
        <mesh filename="../meshes/dg5f_left/visual/ll_dg_1_3.dae" />
      </geometry>
    </visual>
    <collision>
      <origin xyz="0 0 0" rpy="0 0 0" />
      <geometry>
        <mesh filename="../meshes/dg5f_left/collision/ll_dg_1_3_c.STL" />
      </geometry>
    </collision>
  </link>
  <joint name="lj_dg_1_3" type="revolute">
    <origin xyz="0.0 -0.031 0.0" rpy="0.0 0.0 0.0" />
    <parent link="ll_dg_1_2" />
    <child link="ll_dg_1_3" />
    <axis xyz="1 0 0" />
    <limit lower="-1.5707963267948966" upper="1.5707963267948966" effort="7.5" velocity="3.141592653589793"/>
  </joint>

  <link name="ll_dg_1_4">
    <inertial>
      <origin xyz="0.00020482 -0.018795 -0.00036539" rpy="0.0 0.0 0.0" />
      <inertia ixx="9.4915E-06" ixy="-1.5157E-07" ixz="-3.4626E-09" iyy="2.9391E-06" iyz="-3.7813E-07" izz="9.8194E-06" />
      <mass value="0.045" />
    </inertial>
    <visual>
      <origin xyz="0 0 0" rpy="0 0 0" />
      <geometry>
        <mesh filename="../meshes/dg5f_left/visual/ll_dg_1_4.dae" />
      </geometry>
    </visual>
    <collision>
      <origin xyz="0 0 0" rpy="0 0 0" />
      <geometry>
        <mesh filename="../meshes/dg5f_left/collision/ll_dg_1_4_c.STL" />
      </geometry>
    </collision>
  </link>
  <joint name="lj_dg_1_4" type="revolute">
    <origin xyz="0.0 -0.0388 0.0" rpy="0.0 0.0 0.0" />
    <parent link="ll_dg_1_3" />
    <child link="ll_dg_1_4" />
    <axis xyz="1 0 0" />
    <limit lower="-1.5707963267948966" upper="1.5707963267948966" effort="7.5" velocity="3.141592653589793"/>
  </joint>

  <link name="ll_dg_1_tip">
    <inertial>
      <origin xyz="-5.479E-07 -0.007157 0.0038063" rpy="0.0 0.0 0.0" />
      <inertia ixx="1.9895E-07" ixy="-3.0731E-11" ixz="-2.1191E-12" iyy="2.5698E-07" iyz="-1.3375E-08" izz="3.2445E-07" />
      <mass value="0.005" />
    </inertial>
    <visual>
      <origin xyz="0 0 0" rpy="0 0 0" />
      <geometry>
        <mesh filename="../meshes/dg5f_left/visual/ll_dg_1_tip.dae" />
      </geometry>
    </visual>
    <collision>
      <origin xyz="0 0 0" rpy="0 0 0" />
      <geometry>
        <mesh filename="../meshes/dg5f_left/collision/ll_dg_1_tip_c.STL" />
      </geometry>
    </collision>
  </link>
  <joint name="lj_dg_1_tip" type="fixed">
    <origin xyz="0.0 -0.0363 0.0" rpy="0.0 0.0 0.0" />
    <parent link="ll_dg_1_4" />
    <child link="ll_dg_1_tip" />
  </joint>

  <link name="ll_dg_2_1">
    <inertial>
      <origin xyz="0.0010606 -0.00058566 0.023499" rpy="0.0 0.0 0.0" />
      <inertia ixx="6.5541E-06" ixy="1.8684E-07" ixz="-1.1508E-06" iyy="9.5306E-06" iyz="-5.3298E-09" izz="7.0879E-06" />
      <mass value="0.045" />
    </inertial>
    <visual>
      <origin xyz="0 0 0" rpy="0 0 0" />
      <geometry>
        <mesh filename="../meshes/dg5f_left/visual/ll_dg_2_1.dae" />
      </geometry>
    </visual>
    <collision>
      <origin xyz="0 0 0" rpy="0 0 0" />
      <geometry>
        <mesh filename="../meshes/dg5f_left/collision/ll_dg_2_1_c.STL" />
      </geometry>
    </collision>
  </link>
  <joint name="lj_dg_2_1" type="revolute">
    <origin xyz="-0.0071 -0.027 0.0661" rpy="0.0 0.0 0.0" />
    <parent link="ll_dg_palm" />
    <child link="ll_dg_2_1" />
    <axis xyz="1 0 0" />
    <limit lower="-0.6108652381980153" upper="0.4188790204786391" effort="7.5" velocity="3.141592653589793"/>
  </joint>

  <link name="ll_dg_2_2">
    <inertial>
      <origin xyz="-4.7446E-06 2.3008E-05 0.023958" rpy="0.0 0.0 0.0" />
      <inertia ixx="6.4181E-06" ixy="1.3678E-09" ixz="-2.3552E-09" iyy="5.9794E-06" iyz="3.6014E-07" izz="2.458E-06" />
      <mass value="0.045" />
    </inertial>
    <visual>
      <origin xyz="0 0 0" rpy="0 0 0" />
      <geometry>
        <mesh filename="../meshes/dg5f_left/visual/ll_dg_2_2.dae" />
      </geometry>
    </visual>
    <collision>
      <origin xyz="0 0 0" rpy="0 0 0" />
      <geometry>
        <mesh filename="../meshes/dg5f_left/collision/ll_dg_2_2_c.STL" />
      </geometry>
    </collision>
  </link>
  <joint name="lj_dg_2_2" type="revolute">
    <origin xyz="0.01765 0.0 0.0265" rpy="0.0 0.0 0.0" />
    <parent link="ll_dg_2_1" />
    <child link="ll_dg_2_2" />
    <axis xyz="0 1 0" />
    <limit lower="-0.0" upper="2.007128639793479" effort="7.5" velocity="3.141592653589793"/>
  </joint>

  <link name="ll_dg_2_3">
    <inertial>
      <origin xyz="-4.7446E-06 2.3008E-05 0.023958" rpy="0.0 0.0 0.0" />
      <inertia ixx="6.4181E-06" ixy="1.3678E-09" ixz="-2.3552E-09" iyy="5.9794E-06" iyz="3.6014E-07" izz="2.458E-06" />
      <mass value="0.045" />
    </inertial>
    <visual>
      <origin xyz="0 0 0" rpy="0 0 0" />
      <geometry>
        <mesh filename="../meshes/dg5f_left/visual/ll_dg_2_3.dae" />
      </geometry>
    </visual>
    <collision>
      <origin xyz="0 0 0" rpy="0 0 0" />
      <geometry>
        <mesh filename="../meshes/dg5f_left/collision/ll_dg_2_3_c.STL" />
      </geometry>
    </collision>
  </link>
  <joint name="lj_dg_2_3" type="revolute">
    <origin xyz="0.0 0.0 0.0388" rpy="0.0 0.0 0.0" />
    <parent link="ll_dg_2_2" />
    <child link="ll_dg_2_3" />
    <axis xyz="0 1 0" />
    <limit lower="-1.5707963267948966" upper="1.5707963267948966" effort="7.5" velocity="3.141592653589793"/>
  </joint>

  <link name="ll_dg_2_4">
    <inertial>
      <origin xyz="-0.00070816 0.00043036 0.017842" rpy="0.0 0.0 0.0" />
      <inertia ixx="2.8592E-06" ixy="-5.9306E-09" ixz="2.1028E-07" iyy="2.3907E-06" iyz="1.8286E-07" izz="1.6592E-06" />
      <mass value="0.025" />
    </inertial>
    <visual>
      <origin xyz="0 0 0" rpy="0 0 0" />
      <geometry>
        <mesh filename="../meshes/dg5f_left/visual/ll_dg_2_4.dae" />
      </geometry>
    </visual>
    <collision>
      <origin xyz="0 0 0" rpy="0 0 0" />
      <geometry>
        <mesh filename="../meshes/dg5f_left/collision/ll_dg_2_4_c.STL" />
      </geometry>
    </collision>
  </link>
  <joint name="lj_dg_2_4" type="revolute">
    <origin xyz="0.0 0.0 0.0388" rpy="0.0 0.0 0.0" />
    <parent link="ll_dg_2_3" />
    <child link="ll_dg_2_4" />
    <axis xyz="0 1 0" />
    <limit lower="-1.5707963267948966" upper="1.5707963267948966" effort="7.5" velocity="3.141592653589793"/>
  </joint>

  <link name="ll_dg_2_tip">
    <inertial>
      <origin xyz="0.0038063 5.479E-07 0.007157" rpy="0.0 0.0 0.0" />
      <inertia ixx="3.2445E-07" ixy="2.1191E-12" ixz="1.3375E-08" iyy="1.9895E-07" iyz="-3.0731E-11" izz="2.5698E-07" />
      <mass value="0.005" />
    </inertial>
    <visual>
      <origin xyz="0 0 0" rpy="0 0 0" />
      <geometry>
        <mesh filename="../meshes/dg5f_left/visual/ll_dg_2_tip.dae" />
      </geometry>
    </visual>
    <collision>
      <origin xyz="0 0 0" rpy="0 0 0" />
      <geometry>
        <mesh filename="../meshes/dg5f_left/collision/ll_dg_2_tip_c.STL" />
      </geometry>
    </collision>
  </link>
  <joint name="lj_dg_2_tip" type="fixed">
    <origin xyz="0.0 0.0 0.0255" rpy="0.0 0.0 0.0" />
    <parent link="ll_dg_2_4" />
    <child link="ll_dg_2_tip" />
  </joint>

  <link name="ll_dg_3_1">
    <inertial>
      <origin xyz="0.0012558 -0.00017703 0.023374" rpy="0.0 0.0 0.0" />
      <inertia ixx="6.233E-06" ixy="1.1315E-07" ixz="-1.1589E-06" iyy="9.3331E-06" iyz="3.5383E-08" izz="6.7817E-06" />
      <mass value="0.045" />
    </inertial>
    <visual>
      <origin xyz="0 0 0" rpy="0 0 0" />
      <geometry>
        <mesh filename="../meshes/dg5f_left/visual/ll_dg_3_1.dae" />
      </geometry>
    </visual>
    <collision>
      <origin xyz="0 0 0" rpy="0 0 0" />
      <geometry>
        <mesh filename="../meshes/dg5f_left/collision/ll_dg_3_1_c.STL" />
      </geometry>
    </collision>
  </link>
  <joint name="lj_dg_3_1" type="revolute">
    <origin xyz="-0.0071 -0.0025 0.0701" rpy="0.0 0.0 0.0" />
    <parent link="ll_dg_palm" />
    <child link="ll_dg_3_1" />
    <axis xyz="1 0 0" />
    <limit lower="-0.6108652381980153" upper="0.6108652381980153" effort="7.5" velocity="3.141592653589793"/>
  </joint>

  <link name="ll_dg_3_2">
    <inertial>
      <origin xyz="-4.7446E-06 2.3008E-05 0.023958" rpy="0.0 0.0 0.0" />
      <inertia ixx="6.4181E-06" ixy="1.3678E-09" ixz="-2.3552E-09" iyy="5.9794E-06" iyz="3.6014E-07" izz="2.458E-06" />
      <mass value="0.045" />
    </inertial>
    <visual>
      <origin xyz="0 0 0" rpy="0 0 0" />
      <geometry>
        <mesh filename="../meshes/dg5f_left/visual/ll_dg_3_2.dae" />
      </geometry>
    </visual>
    <collision>
      <origin xyz="0 0 0" rpy="0 0 0" />
      <geometry>
        <mesh filename="../meshes/dg5f_left/collision/ll_dg_3_2_c.STL" />
      </geometry>
    </collision>
  </link>
  <joint name="lj_dg_3_2" type="revolute">
    <origin xyz="0.01765 0.0 0.0265" rpy="0.0 0.0 0.0" />
    <parent link="ll_dg_3_1" />
    <child link="ll_dg_3_2" />
    <axis xyz="0 1 0" />
    <limit lower="0.0" upper="1.9547687622336491" effort="7.5" velocity="3.141592653589793"/>
  </joint>

  <link name="ll_dg_3_3">
    <inertial>
      <origin xyz="-4.7446E-06 2.3008E-05 0.023958" rpy="0.0 0.0 0.0" />
      <inertia ixx="6.4181E-06" ixy="1.3678E-09" ixz="-2.3552E-09" iyy="5.9794E-06" iyz="3.6014E-07" izz="2.458E-06" />
      <mass value="0.045" />
    </inertial>
    <visual>
      <origin xyz="0 0 0" rpy="0 0 0" />
      <geometry>
        <mesh filename="../meshes/dg5f_left/visual/ll_dg_3_3.dae" />
      </geometry>
    </visual>
    <collision>
      <origin xyz="0 0 0" rpy="0 0 0" />
      <geometry>
        <mesh filename="../meshes/dg5f_left/collision/ll_dg_3_3_c.STL" />
      </geometry>
    </collision>
  </link>
  <joint name="lj_dg_3_3" type="revolute">
    <origin xyz="0.0 0.0 0.0388" rpy="0.0 0.0 0.0" />
    <parent link="ll_dg_3_2" />
    <child link="ll_dg_3_3" />
    <axis xyz="0 1 0" />
    <limit lower="-1.5707963267948966" upper="1.5707963267948966" effort="7.5" velocity="3.141592653589793"/>
  </joint>

  <link name="ll_dg_3_4">
    <inertial>
      <origin xyz="-0.00070816 0.00043036 0.017842" rpy="0.0 0.0 0.0" />
      <inertia ixx="2.8592E-06" ixy="-5.9306E-09" ixz="2.1028E-07" iyy="2.3907E-06" iyz="1.8286E-07" izz="1.6592E-06" />
      <mass value="0.025" />
    </inertial>
    <visual>
      <origin xyz="0 0 0" rpy="0 0 0" />
      <geometry>
        <mesh filename="../meshes/dg5f_left/visual/ll_dg_3_4.dae" />
      </geometry>
    </visual>
    <collision>
      <origin xyz="0 0 0" rpy="0 0 0" />
      <geometry>
        <mesh filename="../meshes/dg5f_left/collision/ll_dg_3_4_c.STL" />
      </geometry>
    </collision>
  </link>
  <joint name="lj_dg_3_4" type="revolute">
    <origin xyz="0.0 0.0 0.0388" rpy="0.0 0.0 0.0" />
    <parent link="ll_dg_3_3" />
    <child link="ll_dg_3_4" />
    <axis xyz="0 1 0" />
    <limit lower="-1.5707963267948966" upper="1.5707963267948966" effort="7.5" velocity="3.141592653589793"/>
  </joint>

  <link name="ll_dg_3_tip">
    <inertial>
      <origin xyz="0.0038063 5.479E-07 0.007157" rpy="0.0 0.0 0.0" />
      <inertia ixx="3.2445E-07" ixy="2.1191E-12" ixz="1.3375E-08" iyy="1.9895E-07" iyz="-3.0731E-11" izz="2.5698E-07" />
      <mass value="0.005" />
    </inertial>
    <visual>
      <origin xyz="0 0 0" rpy="0 0 0" />
      <geometry>
        <mesh filename="../meshes/dg5f_left/visual/ll_dg_3_tip.dae" />
      </geometry>
    </visual>
    <collision>
      <origin xyz="0 0 0" rpy="0 0 0" />
      <geometry>
        <mesh filename="../meshes/dg5f_left/collision/ll_dg_3_tip_c.STL" />
      </geometry>
    </collision>
  </link>
  <joint name="lj_dg_3_tip" type="fixed">
    <origin xyz="0.0 0.0 0.0255" rpy="0.0 0.0 0.0" />
    <parent link="ll_dg_3_4" />
    <child link="ll_dg_3_tip" />
  </joint>

  <link name="ll_dg_4_1">
    <inertial>
      <origin xyz="0.001061 0.00024417 0.023499" rpy="0.0 0.0 0.0" />
      <inertia ixx="6.5538E-06" ixy="3.9294E-08" ixz="-1.1507E-06" iyy="9.5305E-06" iyz="7.6072E-08" izz="7.0877E-06" />
      <mass value="0.045" />
    </inertial>
    <visual>
      <origin xyz="0 0 0" rpy="0 0 0" />
      <geometry>
        <mesh filename="../meshes/dg5f_left/visual/ll_dg_4_1.dae" />
      </geometry>
    </visual>
    <collision>
      <origin xyz="0 0 0" rpy="0 0 0" />
      <geometry>
        <mesh filename="../meshes/dg5f_left/collision/ll_dg_4_1_c.STL" />
      </geometry>
    </collision>
  </link>
  <joint name="lj_dg_4_1" type="revolute">
    <origin xyz="-0.0071 0.022 0.0621" rpy="0.0 0.0 0.0" />
    <parent link="ll_dg_palm" />
    <child link="ll_dg_4_1" />
    <axis xyz="1 0 0" />
    <limit lower="-0.4188790204786391" upper="0.6108652381980153" effort="7.5" velocity="3.141592653589793"/>
  </joint>

  <link name="ll_dg_4_2">
    <inertial>
      <origin xyz="-4.7446E-06 2.3008E-05 0.023958" rpy="0.0 0.0 0.0" />
      <inertia ixx="6.4181E-06" ixy="1.3678E-09" ixz="-2.3552E-09" iyy="5.9794E-06" iyz="3.6014E-07" izz="2.458E-06" />
      <mass value="0.045" />
    </inertial>
    <visual>
      <origin xyz="0 0 0" rpy="0 0 0" />
      <geometry>
        <mesh filename="../meshes/dg5f_left/visual/ll_dg_4_2.dae" />
      </geometry>
    </visual>
    <collision>
      <origin xyz="0 0 0" rpy="0 0 0" />
      <geometry>
        <mesh filename="../meshes/dg5f_left/collision/ll_dg_4_2_c.STL" />
      </geometry>
    </collision>
  </link>
  <joint name="lj_dg_4_2" type="revolute">
    <origin xyz="0.01765 0.0 0.0265" rpy="0.0 0.0 0.0" />
    <parent link="ll_dg_4_1" />
    <child link="ll_dg_4_2" />
    <axis xyz="0 1 0" />
    <limit lower="0.0" upper="1.9024088846738192" effort="7.5" velocity="3.141592653589793"/>
  </joint>

  <link name="ll_dg_4_3">
    <inertial>
      <origin xyz="-4.7446E-06 2.3008E-05 0.023958" rpy="0.0 0.0 0.0" />
      <inertia ixx="6.4181E-06" ixy="1.3678E-09" ixz="-2.3552E-09" iyy="5.9794E-06" iyz="3.6014E-07" izz="2.458E-06" />
      <mass value="0.045" />
    </inertial>
    <visual>
      <origin xyz="0 0 0" rpy="0 0 0" />
      <geometry>
        <mesh filename="../meshes/dg5f_left/visual/ll_dg_4_3.dae" />
      </geometry>
    </visual>
    <collision>
      <origin xyz="0 0 0" rpy="0 0 0" />
      <geometry>
        <mesh filename="../meshes/dg5f_left/collision/ll_dg_4_3_c.STL" />
      </geometry>
    </collision>
  </link>
  <joint name="lj_dg_4_3" type="revolute">
    <origin xyz="0.0 0.0 0.0388" rpy="0.0 0.0 0.0" />
    <parent link="ll_dg_4_2" />
    <child link="ll_dg_4_3" />
    <axis xyz="0 1 0" />
    <limit lower="-1.5707963267948966" upper="1.5707963267948966" effort="7.5" velocity="3.141592653589793"/>
  </joint>

  <link name="ll_dg_4_4">
    <inertial>
      <origin xyz="-0.00070816 0.00043036 0.017842" rpy="0.0 0.0 0.0" />
      <inertia ixx="2.8592E-06" ixy="-5.9306E-09" ixz="2.1028E-07" iyy="2.3907E-06" iyz="1.8286E-07" izz="1.6592E-06" />
      <mass value="0.025" />
    </inertial>
    <visual>
      <origin xyz="0 0 0" rpy="0 0 0" />
      <geometry>
        <mesh filename="../meshes/dg5f_left/visual/ll_dg_4_4.dae" />
      </geometry>
    </visual>
    <collision>
      <origin xyz="0 0 0" rpy="0 0 0" />
      <geometry>
        <mesh filename="../meshes/dg5f_left/collision/ll_dg_4_4_c.STL" />
      </geometry>
    </collision>
  </link>
  <joint name="lj_dg_4_4" type="revolute">
    <origin xyz="0.0 0.0 0.0388" rpy="0.0 0.0 0.0" />
    <parent link="ll_dg_4_3" />
    <child link="ll_dg_4_4" />
    <axis xyz="0 1 0" />
    <limit lower="-1.5707963267948966" upper="1.5707963267948966" effort="7.5" velocity="3.141592653589793"/>
  </joint>

  <link name="ll_dg_4_tip">
    <inertial>
      <origin xyz="0.0038063 5.479E-07 0.007157" rpy="0.0 0.0 0.0" />
      <inertia ixx="3.2445E-07" ixy="2.1191E-12" ixz="1.3375E-08" iyy="1.9895E-07" iyz="-3.0731E-11" izz="2.5698E-07" />
      <mass value="0.005" />
    </inertial>
    <visual>
      <origin xyz="0 0 0" rpy="0 0 0" />
      <geometry>
        <mesh filename="../meshes/dg5f_left/visual/ll_dg_4_tip.dae" />
      </geometry>
    </visual>
    <collision>
      <origin xyz="0 0 0" rpy="0 0 0" />
      <geometry>
        <mesh filename="../meshes/dg5f_left/collision/ll_dg_4_tip_c.STL" />
      </geometry>
    </collision>
  </link>
  <joint name="lj_dg_4_tip" type="fixed">
    <origin xyz="0.0 0.0 0.0255" rpy="0.0 0.0 0.0" />
    <parent link="ll_dg_4_4" />
    <child link="ll_dg_4_tip" />
  </joint>

  <link name="ll_dg_5_1">
    <inertial>
      <origin xyz="-0.0045287 0.025016 0.014025" rpy="0.0 0.0 0.0" />
      <inertia ixx="2.3621E-05" ixy="-2.0571E-07" ixz="2.5894E-06" iyy="2.3655E-05" iyz="-4.4786E-06" izz="1.1298E-05" />
      <mass value="0.055" />
    </inertial>
    <visual>
      <origin xyz="0 0 0" rpy="0 0 0" />
      <geometry>
        <mesh filename="../meshes/dg5f_left/visual/ll_dg_5_1.dae" />
      </geometry>
    </visual>
    <collision>
      <origin xyz="0 0 0" rpy="0 0 0" />
      <geometry>
        <mesh filename="../meshes/dg5f_left/collision/ll_dg_5_1_c.STL" />
      </geometry>
    </collision>
  </link>
  <joint name="lj_dg_5_1" type="revolute">
    <origin xyz="0.0103 0.0195 0.0182" rpy="0.0 0.0 0.0" />
    <parent link="ll_dg_palm" />
    <child link="ll_dg_5_1" />
    <axis xyz="0 0 1" />
    <limit lower="-1.0471975511965976" upper="0.017453292519943295" effort="7.5" velocity="3.141592653589793"/>
  </joint>

  <link name="ll_dg_5_2">
    <inertial>
      <origin xyz="0.00055633 0.00055633 0.0155" rpy="0.0 0.0 0.0" />
      <inertia ixx="1.9935E-06" ixy="3.114E-09" ixz="1.5774E-07" iyy="1.9935E-06" iyz="-1.5774E-07" izz="1.459E-06" />
      <mass value="0.025" />
    </inertial>
    <visual>
      <origin xyz="0 0 0" rpy="0 0 0" />
      <geometry>
        <mesh filename="../meshes/dg5f_left/visual/ll_dg_5_2.dae" />
      </geometry>
    </visual>
    <collision>
      <origin xyz="0 0 0" rpy="0 0 0" />
      <geometry>
        <mesh filename="../meshes/dg5f_left/collision/ll_dg_5_2_c.STL" />
      </geometry>
    </collision>
  </link>
  <joint name="lj_dg_5_2" type="revolute">
    <origin xyz="0.0 0.028 0.0381" rpy="0.0 0.0 0.0" />
    <parent link="ll_dg_5_1" />
    <child link="ll_dg_5_2" />
    <axis xyz="1 0 0" />
    <limit lower="-0.6108652381980153" upper="0.4188790204786391" effort="7.5" velocity="3.141592653589793"/>
  </joint>

  <link name="ll_dg_5_3">
    <inertial>
      <origin xyz="4.7446E-06 2.3008E-05 0.014842" rpy="0.0 0.0 0.0" />
      <inertia ixx="6.4181E-06" ixy="-1.3678E-09" ixz="-2.3552E-09" iyy="5.9794E-06" iyz="-3.6014E-07" izz="2.458E-06" />
      <mass value="0.045" />
    </inertial>
    <visual>
      <origin xyz="0 0 0" rpy="0 0 0" />
      <geometry>
        <mesh filename="../meshes/dg5f_left/visual/ll_dg_5_3.dae" />
      </geometry>
    </visual>
    <collision>
      <origin xyz="0 0 0" rpy="0 0 0" />
      <geometry>
        <mesh filename="../meshes/dg5f_left/collision/ll_dg_5_3_c.STL" />
      </geometry>
    </collision>
  </link>
  <joint name="lj_dg_5_3" type="revolute">
    <origin xyz="0.0 0.0 0.031" rpy="0.0 0.0 0.0" />
    <parent link="ll_dg_5_2" />
    <child link="ll_dg_5_3" />
    <axis xyz="0 1 0" />
    <limit lower="-1.5707963267948966" upper="1.5707963267948966" effort="7.5" velocity="3.141592653589793"/>
  </joint>

  <link name="ll_dg_5_4">
    <inertial>
      <origin xyz="-0.00036539 -0.00020482 0.018795" rpy="0.0 0.0 0.0" />
      <inertia ixx="9.8194E-06" ixy="3.4626E-09" ixz="3.7813E-07" iyy="9.4915E-06" iyz="-1.5157E-07" izz="2.9391E-06" />
      <mass value="0.045" />
    </inertial>
    <visual>
      <origin xyz="0 0 0" rpy="0 0 0" />
      <geometry>
        <mesh filename="../meshes/dg5f_left/visual/ll_dg_5_4.dae" />
      </geometry>
    </visual>
    <collision>
      <origin xyz="0 0 0" rpy="0 0 0" />
      <geometry>
        <mesh filename="../meshes/dg5f_left/collision/ll_dg_5_4_c.STL" />
      </geometry>
    </collision>
  </link>
  <joint name="lj_dg_5_4" type="revolute">
    <origin xyz="0.0 0.0 0.0388" rpy="0.0 0.0 0.0" />
    <parent link="ll_dg_5_3" />
    <child link="ll_dg_5_4" />
    <axis xyz="0 1 0" />
    <limit lower="-1.5707963267948966" upper="1.5707963267948966" effort="7.5" velocity="3.141592653589793"/>
  </joint>

  <link name="ll_dg_5_tip">
    <inertial>
      <origin xyz="0.0038063 5.479E-07 0.007157" rpy="0.0 0.0 0.0" />
      <inertia ixx="3.2445E-07" ixy="2.1191E-12" ixz="1.3375E-08" iyy="1.9895E-07" iyz="-3.0731E-11" izz="2.5698E-07" />
      <mass value="0.005" />
    </inertial>
    <visual>
      <origin xyz="0 0 0" rpy="0 0 0" />
      <geometry>
        <mesh filename="../meshes/dg5f_left/visual/ll_dg_5_tip.dae" />
      </geometry>
    </visual>
    <collision>
      <origin xyz="0 0 0" rpy="0 0 0" />
      <geometry>
        <mesh filename="../meshes/dg5f_left/collision/ll_dg_5_tip_c.STL" />
      </geometry>
    </collision>
  </link>
  <joint name="lj_dg_5_tip" type="fixed">
    <origin xyz="0.0 0.0 0.0363" rpy="0.0 0.0 0.0" />
    <parent link="ll_dg_5_4" />
    <child link="ll_dg_5_tip" />
  </joint>
</robot>
